[2023-09-18T14:27:31.982+0000] {taskinstance.py:1157} INFO - Dependencies all met for dep_context=non-requeueable deps ti=<TaskInstance: 6.2-monitoring.task4 scheduled__2023-09-01T00:00:00+00:00 [queued]>
[2023-09-18T14:27:31.994+0000] {taskinstance.py:1157} INFO - Dependencies all met for dep_context=requeueable deps ti=<TaskInstance: 6.2-monitoring.task4 scheduled__2023-09-01T00:00:00+00:00 [queued]>
[2023-09-18T14:27:31.995+0000] {taskinstance.py:1359} INFO - Starting attempt 1 of 3
[2023-09-18T14:27:32.011+0000] {taskinstance.py:1380} INFO - Executing <Task(PythonOperator): task4> on 2023-09-01 00:00:00+00:00
[2023-09-18T14:27:32.017+0000] {standard_task_runner.py:57} INFO - Started process 5989 to run task
[2023-09-18T14:27:32.021+0000] {standard_task_runner.py:84} INFO - Running: ['***', 'tasks', 'run', '6.2-monitoring', 'task4', 'scheduled__2023-09-01T00:00:00+00:00', '--job-id', '517', '--raw', '--subdir', 'DAGS_FOLDER/6.2-monitoring.py', '--cfg-path', '/tmp/tmp1va9wlek']
[2023-09-18T14:27:32.022+0000] {standard_task_runner.py:85} INFO - Job 517: Subtask task4
[2023-09-18T14:27:32.078+0000] {task_command.py:415} INFO - Running <TaskInstance: 6.2-monitoring.task4 scheduled__2023-09-01T00:00:00+00:00 [running]> on host e891a57bf0af
[2023-09-18T14:27:32.166+0000] {taskinstance.py:1660} INFO - Exporting env vars: AIRFLOW_CTX_DAG_OWNER='***' AIRFLOW_CTX_DAG_ID='6.2-monitoring' AIRFLOW_CTX_TASK_ID='task4' AIRFLOW_CTX_EXECUTION_DATE='2023-09-01T00:00:00+00:00' AIRFLOW_CTX_TRY_NUMBER='1' AIRFLOW_CTX_DAG_RUN_ID='scheduled__2023-09-01T00:00:00+00:00'
[2023-09-18T14:27:32.168+0000] {taskinstance.py:1935} ERROR - Task failed with exception
Traceback (most recent call last):
  File "/home/airflow/.local/lib/python3.8/site-packages/airflow/operators/python.py", line 192, in execute
    return_value = self.execute_callable()
  File "/home/airflow/.local/lib/python3.8/site-packages/airflow/operators/python.py", line 209, in execute_callable
    return self.python_callable(*self.op_args, **self.op_kwargs)
  File "/opt/airflow/dags/6.2-monitoring.py", line 9, in myfunction
    raise Exception
Exception
[2023-09-18T14:27:32.187+0000] {taskinstance.py:1398} INFO - Marking task as UP_FOR_RETRY. dag_id=6.2-monitoring, task_id=task4, execution_date=20230901T000000, start_date=20230918T142731, end_date=20230918T142732
[2023-09-18T14:27:32.201+0000] {standard_task_runner.py:104} ERROR - Failed to execute job 517 for task task4 (; 5989)
[2023-09-18T14:27:32.234+0000] {local_task_job_runner.py:228} INFO - Task exited with return code 1
[2023-09-18T14:27:32.260+0000] {taskinstance.py:2776} INFO - 0 downstream tasks scheduled from follow-on schedule check
[2023-09-19T12:15:25.566+0000] {taskinstance.py:1157} INFO - Dependencies all met for dep_context=non-requeueable deps ti=<TaskInstance: 6.2-monitoring.task4 scheduled__2023-09-01T00:00:00+00:00 [queued]>
[2023-09-19T12:15:25.609+0000] {taskinstance.py:1157} INFO - Dependencies all met for dep_context=requeueable deps ti=<TaskInstance: 6.2-monitoring.task4 scheduled__2023-09-01T00:00:00+00:00 [queued]>
[2023-09-19T12:15:25.610+0000] {taskinstance.py:1359} INFO - Starting attempt 1 of 3
[2023-09-19T12:15:25.630+0000] {taskinstance.py:1380} INFO - Executing <Task(PythonOperator): task4> on 2023-09-01 00:00:00+00:00
[2023-09-19T12:15:25.637+0000] {standard_task_runner.py:57} INFO - Started process 110 to run task
[2023-09-19T12:15:25.655+0000] {standard_task_runner.py:84} INFO - Running: ['***', 'tasks', 'run', '6.2-monitoring', 'task4', 'scheduled__2023-09-01T00:00:00+00:00', '--job-id', '528', '--raw', '--subdir', 'DAGS_FOLDER/6.2-monitoring.py', '--cfg-path', '/tmp/tmp2f6vi8ku']
[2023-09-19T12:15:25.661+0000] {standard_task_runner.py:85} INFO - Job 528: Subtask task4
[2023-09-19T12:15:25.757+0000] {task_command.py:415} INFO - Running <TaskInstance: 6.2-monitoring.task4 scheduled__2023-09-01T00:00:00+00:00 [running]> on host e891a57bf0af
[2023-09-19T12:15:25.885+0000] {taskinstance.py:1660} INFO - Exporting env vars: AIRFLOW_CTX_DAG_OWNER='***' AIRFLOW_CTX_DAG_ID='6.2-monitoring' AIRFLOW_CTX_TASK_ID='task4' AIRFLOW_CTX_EXECUTION_DATE='2023-09-01T00:00:00+00:00' AIRFLOW_CTX_TRY_NUMBER='1' AIRFLOW_CTX_DAG_RUN_ID='scheduled__2023-09-01T00:00:00+00:00'
[2023-09-19T12:15:25.888+0000] {taskinstance.py:1935} ERROR - Task failed with exception
Traceback (most recent call last):
  File "/home/airflow/.local/lib/python3.8/site-packages/airflow/operators/python.py", line 192, in execute
    return_value = self.execute_callable()
  File "/home/airflow/.local/lib/python3.8/site-packages/airflow/operators/python.py", line 209, in execute_callable
    return self.python_callable(*self.op_args, **self.op_kwargs)
  File "/opt/airflow/dags/6.2-monitoring.py", line 9, in myfunction
    raise Exception
Exception
[2023-09-19T12:15:25.906+0000] {taskinstance.py:1398} INFO - Marking task as UP_FOR_RETRY. dag_id=6.2-monitoring, task_id=task4, execution_date=20230901T000000, start_date=20230919T121525, end_date=20230919T121525
[2023-09-19T12:15:25.923+0000] {standard_task_runner.py:104} ERROR - Failed to execute job 528 for task task4 (; 110)
[2023-09-19T12:15:25.944+0000] {local_task_job_runner.py:228} INFO - Task exited with return code 1
[2023-09-19T12:15:25.981+0000] {taskinstance.py:2776} INFO - 0 downstream tasks scheduled from follow-on schedule check
