[2023-09-18T14:27:38.561+0000] {taskinstance.py:1157} INFO - Dependencies all met for dep_context=non-requeueable deps ti=<TaskInstance: 6.2-monitoring.task4 scheduled__2023-09-01T00:00:00+00:00 [queued]>
[2023-09-18T14:27:38.572+0000] {taskinstance.py:1157} INFO - Dependencies all met for dep_context=requeueable deps ti=<TaskInstance: 6.2-monitoring.task4 scheduled__2023-09-01T00:00:00+00:00 [queued]>
[2023-09-18T14:27:38.573+0000] {taskinstance.py:1359} INFO - Starting attempt 2 of 3
[2023-09-18T14:27:38.592+0000] {taskinstance.py:1380} INFO - Executing <Task(PythonOperator): task4> on 2023-09-01 00:00:00+00:00
[2023-09-18T14:27:38.597+0000] {standard_task_runner.py:57} INFO - Started process 6002 to run task
[2023-09-18T14:27:38.600+0000] {standard_task_runner.py:84} INFO - Running: ['***', 'tasks', 'run', '6.2-monitoring', 'task4', 'scheduled__2023-09-01T00:00:00+00:00', '--job-id', '519', '--raw', '--subdir', 'DAGS_FOLDER/6.2-monitoring.py', '--cfg-path', '/tmp/tmp_l7vvsc1']
[2023-09-18T14:27:38.602+0000] {standard_task_runner.py:85} INFO - Job 519: Subtask task4
[2023-09-18T14:27:38.656+0000] {task_command.py:415} INFO - Running <TaskInstance: 6.2-monitoring.task4 scheduled__2023-09-01T00:00:00+00:00 [running]> on host e891a57bf0af
[2023-09-18T14:27:38.744+0000] {taskinstance.py:1660} INFO - Exporting env vars: AIRFLOW_CTX_DAG_OWNER='***' AIRFLOW_CTX_DAG_ID='6.2-monitoring' AIRFLOW_CTX_TASK_ID='task4' AIRFLOW_CTX_EXECUTION_DATE='2023-09-01T00:00:00+00:00' AIRFLOW_CTX_TRY_NUMBER='2' AIRFLOW_CTX_DAG_RUN_ID='scheduled__2023-09-01T00:00:00+00:00'
[2023-09-18T14:27:38.745+0000] {taskinstance.py:1935} ERROR - Task failed with exception
Traceback (most recent call last):
  File "/home/airflow/.local/lib/python3.8/site-packages/airflow/operators/python.py", line 192, in execute
    return_value = self.execute_callable()
  File "/home/airflow/.local/lib/python3.8/site-packages/airflow/operators/python.py", line 209, in execute_callable
    return self.python_callable(*self.op_args, **self.op_kwargs)
  File "/opt/airflow/dags/6.2-monitoring.py", line 9, in myfunction
    raise Exception
Exception
[2023-09-18T14:27:38.762+0000] {taskinstance.py:1398} INFO - Marking task as UP_FOR_RETRY. dag_id=6.2-monitoring, task_id=task4, execution_date=20230901T000000, start_date=20230918T142738, end_date=20230918T142738
[2023-09-18T14:27:38.774+0000] {standard_task_runner.py:104} ERROR - Failed to execute job 519 for task task4 (; 6002)
[2023-09-18T14:27:38.813+0000] {local_task_job_runner.py:228} INFO - Task exited with return code 1
[2023-09-18T14:27:38.842+0000] {taskinstance.py:2776} INFO - 0 downstream tasks scheduled from follow-on schedule check
[2023-09-19T12:15:31.725+0000] {taskinstance.py:1157} INFO - Dependencies all met for dep_context=non-requeueable deps ti=<TaskInstance: 6.2-monitoring.task4 scheduled__2023-09-01T00:00:00+00:00 [queued]>
[2023-09-19T12:15:31.739+0000] {taskinstance.py:1157} INFO - Dependencies all met for dep_context=requeueable deps ti=<TaskInstance: 6.2-monitoring.task4 scheduled__2023-09-01T00:00:00+00:00 [queued]>
[2023-09-19T12:15:31.740+0000] {taskinstance.py:1359} INFO - Starting attempt 2 of 3
[2023-09-19T12:15:31.759+0000] {taskinstance.py:1380} INFO - Executing <Task(PythonOperator): task4> on 2023-09-01 00:00:00+00:00
[2023-09-19T12:15:31.765+0000] {standard_task_runner.py:57} INFO - Started process 114 to run task
[2023-09-19T12:15:31.769+0000] {standard_task_runner.py:84} INFO - Running: ['***', 'tasks', 'run', '6.2-monitoring', 'task4', 'scheduled__2023-09-01T00:00:00+00:00', '--job-id', '530', '--raw', '--subdir', 'DAGS_FOLDER/6.2-monitoring.py', '--cfg-path', '/tmp/tmpz787t0w_']
[2023-09-19T12:15:31.771+0000] {standard_task_runner.py:85} INFO - Job 530: Subtask task4
[2023-09-19T12:15:31.828+0000] {task_command.py:415} INFO - Running <TaskInstance: 6.2-monitoring.task4 scheduled__2023-09-01T00:00:00+00:00 [running]> on host e891a57bf0af
[2023-09-19T12:15:31.923+0000] {taskinstance.py:1660} INFO - Exporting env vars: AIRFLOW_CTX_DAG_OWNER='***' AIRFLOW_CTX_DAG_ID='6.2-monitoring' AIRFLOW_CTX_TASK_ID='task4' AIRFLOW_CTX_EXECUTION_DATE='2023-09-01T00:00:00+00:00' AIRFLOW_CTX_TRY_NUMBER='2' AIRFLOW_CTX_DAG_RUN_ID='scheduled__2023-09-01T00:00:00+00:00'
[2023-09-19T12:15:31.924+0000] {taskinstance.py:1935} ERROR - Task failed with exception
Traceback (most recent call last):
  File "/home/airflow/.local/lib/python3.8/site-packages/airflow/operators/python.py", line 192, in execute
    return_value = self.execute_callable()
  File "/home/airflow/.local/lib/python3.8/site-packages/airflow/operators/python.py", line 209, in execute_callable
    return self.python_callable(*self.op_args, **self.op_kwargs)
  File "/opt/airflow/dags/6.2-monitoring.py", line 9, in myfunction
    raise Exception
Exception
[2023-09-19T12:15:31.938+0000] {taskinstance.py:1398} INFO - Marking task as UP_FOR_RETRY. dag_id=6.2-monitoring, task_id=task4, execution_date=20230901T000000, start_date=20230919T121531, end_date=20230919T121531
[2023-09-19T12:15:31.953+0000] {standard_task_runner.py:104} ERROR - Failed to execute job 530 for task task4 (; 114)
[2023-09-19T12:15:31.984+0000] {local_task_job_runner.py:228} INFO - Task exited with return code 1
[2023-09-19T12:15:32.018+0000] {taskinstance.py:2776} INFO - 0 downstream tasks scheduled from follow-on schedule check
