[2023-09-18T14:27:44.911+0000] {taskinstance.py:1157} INFO - Dependencies all met for dep_context=non-requeueable deps ti=<TaskInstance: 6.2-monitoring.task4 scheduled__2023-09-01T00:00:00+00:00 [queued]>
[2023-09-18T14:27:44.928+0000] {taskinstance.py:1157} INFO - Dependencies all met for dep_context=requeueable deps ti=<TaskInstance: 6.2-monitoring.task4 scheduled__2023-09-01T00:00:00+00:00 [queued]>
[2023-09-18T14:27:44.928+0000] {taskinstance.py:1359} INFO - Starting attempt 3 of 3
[2023-09-18T14:27:44.950+0000] {taskinstance.py:1380} INFO - Executing <Task(PythonOperator): task4> on 2023-09-01 00:00:00+00:00
[2023-09-18T14:27:44.996+0000] {standard_task_runner.py:57} INFO - Started process 6004 to run task
[2023-09-18T14:27:45.000+0000] {standard_task_runner.py:84} INFO - Running: ['***', 'tasks', 'run', '6.2-monitoring', 'task4', 'scheduled__2023-09-01T00:00:00+00:00', '--job-id', '520', '--raw', '--subdir', 'DAGS_FOLDER/6.2-monitoring.py', '--cfg-path', '/tmp/tmpimjf9f1r']
[2023-09-18T14:27:45.002+0000] {standard_task_runner.py:85} INFO - Job 520: Subtask task4
[2023-09-18T14:27:45.056+0000] {task_command.py:415} INFO - Running <TaskInstance: 6.2-monitoring.task4 scheduled__2023-09-01T00:00:00+00:00 [running]> on host e891a57bf0af
[2023-09-18T14:27:45.137+0000] {taskinstance.py:1660} INFO - Exporting env vars: AIRFLOW_CTX_DAG_OWNER='***' AIRFLOW_CTX_DAG_ID='6.2-monitoring' AIRFLOW_CTX_TASK_ID='task4' AIRFLOW_CTX_EXECUTION_DATE='2023-09-01T00:00:00+00:00' AIRFLOW_CTX_TRY_NUMBER='3' AIRFLOW_CTX_DAG_RUN_ID='scheduled__2023-09-01T00:00:00+00:00'
[2023-09-18T14:27:45.138+0000] {taskinstance.py:1935} ERROR - Task failed with exception
Traceback (most recent call last):
  File "/home/airflow/.local/lib/python3.8/site-packages/airflow/operators/python.py", line 192, in execute
    return_value = self.execute_callable()
  File "/home/airflow/.local/lib/python3.8/site-packages/airflow/operators/python.py", line 209, in execute_callable
    return self.python_callable(*self.op_args, **self.op_kwargs)
  File "/opt/airflow/dags/6.2-monitoring.py", line 9, in myfunction
    raise Exception
Exception
[2023-09-18T14:27:45.152+0000] {taskinstance.py:1398} INFO - Marking task as FAILED. dag_id=6.2-monitoring, task_id=task4, execution_date=20230901T000000, start_date=20230918T142744, end_date=20230918T142745
[2023-09-18T14:27:45.165+0000] {standard_task_runner.py:104} ERROR - Failed to execute job 520 for task task4 (; 6004)
[2023-09-18T14:27:45.173+0000] {local_task_job_runner.py:228} INFO - Task exited with return code 1
[2023-09-18T14:27:45.197+0000] {taskinstance.py:2776} INFO - 0 downstream tasks scheduled from follow-on schedule check
[2023-09-19T12:15:37.716+0000] {taskinstance.py:1157} INFO - Dependencies all met for dep_context=non-requeueable deps ti=<TaskInstance: 6.2-monitoring.task4 scheduled__2023-09-01T00:00:00+00:00 [queued]>
[2023-09-19T12:15:37.795+0000] {taskinstance.py:1157} INFO - Dependencies all met for dep_context=requeueable deps ti=<TaskInstance: 6.2-monitoring.task4 scheduled__2023-09-01T00:00:00+00:00 [queued]>
[2023-09-19T12:15:37.796+0000] {taskinstance.py:1359} INFO - Starting attempt 3 of 3
[2023-09-19T12:15:37.829+0000] {taskinstance.py:1380} INFO - Executing <Task(PythonOperator): task4> on 2023-09-01 00:00:00+00:00
[2023-09-19T12:15:37.836+0000] {standard_task_runner.py:57} INFO - Started process 124 to run task
[2023-09-19T12:15:37.841+0000] {standard_task_runner.py:84} INFO - Running: ['***', 'tasks', 'run', '6.2-monitoring', 'task4', 'scheduled__2023-09-01T00:00:00+00:00', '--job-id', '531', '--raw', '--subdir', 'DAGS_FOLDER/6.2-monitoring.py', '--cfg-path', '/tmp/tmpm54w78wt']
[2023-09-19T12:15:37.843+0000] {standard_task_runner.py:85} INFO - Job 531: Subtask task4
[2023-09-19T12:15:37.920+0000] {task_command.py:415} INFO - Running <TaskInstance: 6.2-monitoring.task4 scheduled__2023-09-01T00:00:00+00:00 [running]> on host e891a57bf0af
[2023-09-19T12:15:38.035+0000] {taskinstance.py:1660} INFO - Exporting env vars: AIRFLOW_CTX_DAG_OWNER='***' AIRFLOW_CTX_DAG_ID='6.2-monitoring' AIRFLOW_CTX_TASK_ID='task4' AIRFLOW_CTX_EXECUTION_DATE='2023-09-01T00:00:00+00:00' AIRFLOW_CTX_TRY_NUMBER='3' AIRFLOW_CTX_DAG_RUN_ID='scheduled__2023-09-01T00:00:00+00:00'
[2023-09-19T12:15:38.036+0000] {taskinstance.py:1935} ERROR - Task failed with exception
Traceback (most recent call last):
  File "/home/airflow/.local/lib/python3.8/site-packages/airflow/operators/python.py", line 192, in execute
    return_value = self.execute_callable()
  File "/home/airflow/.local/lib/python3.8/site-packages/airflow/operators/python.py", line 209, in execute_callable
    return self.python_callable(*self.op_args, **self.op_kwargs)
  File "/opt/airflow/dags/6.2-monitoring.py", line 9, in myfunction
    raise Exception
Exception
[2023-09-19T12:15:38.054+0000] {taskinstance.py:1398} INFO - Marking task as FAILED. dag_id=6.2-monitoring, task_id=task4, execution_date=20230901T000000, start_date=20230919T121537, end_date=20230919T121538
[2023-09-19T12:15:38.071+0000] {standard_task_runner.py:104} ERROR - Failed to execute job 531 for task task4 (; 124)
[2023-09-19T12:15:38.095+0000] {local_task_job_runner.py:228} INFO - Task exited with return code 1
[2023-09-19T12:15:38.132+0000] {taskinstance.py:2776} INFO - 0 downstream tasks scheduled from follow-on schedule check
