[2023-09-18T13:46:36.874+0000] {taskinstance.py:1157} INFO - Dependencies all met for dep_context=non-requeueable deps ti=<TaskInstance: 6.1-monitoring.task2 scheduled__2023-09-03T00:00:00+00:00 [queued]>
[2023-09-18T13:46:36.893+0000] {taskinstance.py:1157} INFO - Dependencies all met for dep_context=requeueable deps ti=<TaskInstance: 6.1-monitoring.task2 scheduled__2023-09-03T00:00:00+00:00 [queued]>
[2023-09-18T13:46:36.896+0000] {taskinstance.py:1359} INFO - Starting attempt 1 of 1
[2023-09-18T13:46:36.922+0000] {taskinstance.py:1380} INFO - Executing <Task(BashOperator): task2> on 2023-09-03 00:00:00+00:00
[2023-09-18T13:46:36.937+0000] {standard_task_runner.py:57} INFO - Started process 4406 to run task
[2023-09-18T13:46:36.945+0000] {standard_task_runner.py:84} INFO - Running: ['***', 'tasks', 'run', '6.1-monitoring', 'task2', 'scheduled__2023-09-03T00:00:00+00:00', '--job-id', '241', '--raw', '--subdir', 'DAGS_FOLDER/6.1-monitoring.py', '--cfg-path', '/tmp/tmpwap136lr']
[2023-09-18T13:46:36.950+0000] {standard_task_runner.py:85} INFO - Job 241: Subtask task2
[2023-09-18T13:46:37.095+0000] {task_command.py:415} INFO - Running <TaskInstance: 6.1-monitoring.task2 scheduled__2023-09-03T00:00:00+00:00 [running]> on host e891a57bf0af
[2023-09-18T13:46:37.360+0000] {taskinstance.py:1660} INFO - Exporting env vars: AIRFLOW_CTX_DAG_OWNER='***' AIRFLOW_CTX_DAG_ID='6.1-monitoring' AIRFLOW_CTX_TASK_ID='task2' AIRFLOW_CTX_EXECUTION_DATE='2023-09-03T00:00:00+00:00' AIRFLOW_CTX_TRY_NUMBER='1' AIRFLOW_CTX_DAG_RUN_ID='scheduled__2023-09-03T00:00:00+00:00'
[2023-09-18T13:46:37.398+0000] {subprocess.py:63} INFO - Tmp dir root location: /tmp
[2023-09-18T13:46:37.401+0000] {subprocess.py:75} INFO - Running command: ['/bin/bash', '-c', "sleep 2 && echo 'Task 2"]
[2023-09-18T13:46:37.440+0000] {subprocess.py:86} INFO - Output:
[2023-09-18T13:46:37.495+0000] {subprocess.py:93} INFO - /bin/bash: -c: line 1: unexpected EOF while looking for matching `''
[2023-09-18T13:46:37.496+0000] {subprocess.py:93} INFO - /bin/bash: -c: line 2: syntax error: unexpected end of file
[2023-09-18T13:46:37.499+0000] {subprocess.py:97} INFO - Command exited with return code 2
[2023-09-18T13:46:37.539+0000] {taskinstance.py:1935} ERROR - Task failed with exception
Traceback (most recent call last):
  File "/home/airflow/.local/lib/python3.8/site-packages/airflow/operators/bash.py", line 210, in execute
    raise AirflowException(
airflow.exceptions.AirflowException: Bash command failed. The command returned a non-zero exit code 2.
[2023-09-18T13:46:37.550+0000] {taskinstance.py:1398} INFO - Marking task as FAILED. dag_id=6.1-monitoring, task_id=task2, execution_date=20230903T000000, start_date=20230918T134636, end_date=20230918T134637
[2023-09-18T13:46:37.608+0000] {standard_task_runner.py:104} ERROR - Failed to execute job 241 for task task2 (Bash command failed. The command returned a non-zero exit code 2.; 4406)
[2023-09-18T13:46:37.631+0000] {local_task_job_runner.py:228} INFO - Task exited with return code 1
[2023-09-18T13:46:37.832+0000] {taskinstance.py:2776} INFO - 0 downstream tasks scheduled from follow-on schedule check
[2023-09-18T13:52:31.715+0000] {taskinstance.py:1157} INFO - Dependencies all met for dep_context=non-requeueable deps ti=<TaskInstance: 6.1-monitoring.task2 scheduled__2023-09-03T00:00:00+00:00 [queued]>
[2023-09-18T13:52:31.735+0000] {taskinstance.py:1157} INFO - Dependencies all met for dep_context=requeueable deps ti=<TaskInstance: 6.1-monitoring.task2 scheduled__2023-09-03T00:00:00+00:00 [queued]>
[2023-09-18T13:52:31.736+0000] {taskinstance.py:1359} INFO - Starting attempt 1 of 1
[2023-09-18T13:52:31.763+0000] {taskinstance.py:1380} INFO - Executing <Task(BashOperator): task2> on 2023-09-03 00:00:00+00:00
[2023-09-18T13:52:31.770+0000] {standard_task_runner.py:57} INFO - Started process 4933 to run task
[2023-09-18T13:52:31.775+0000] {standard_task_runner.py:84} INFO - Running: ['***', 'tasks', 'run', '6.1-monitoring', 'task2', 'scheduled__2023-09-03T00:00:00+00:00', '--job-id', '365', '--raw', '--subdir', 'DAGS_FOLDER/6.1-monitoring.py', '--cfg-path', '/tmp/tmpt_008az8']
[2023-09-18T13:52:31.776+0000] {standard_task_runner.py:85} INFO - Job 365: Subtask task2
[2023-09-18T13:52:31.841+0000] {task_command.py:415} INFO - Running <TaskInstance: 6.1-monitoring.task2 scheduled__2023-09-03T00:00:00+00:00 [running]> on host e891a57bf0af
[2023-09-18T13:52:31.956+0000] {taskinstance.py:1660} INFO - Exporting env vars: AIRFLOW_CTX_DAG_OWNER='***' AIRFLOW_CTX_DAG_ID='6.1-monitoring' AIRFLOW_CTX_TASK_ID='task2' AIRFLOW_CTX_EXECUTION_DATE='2023-09-03T00:00:00+00:00' AIRFLOW_CTX_TRY_NUMBER='1' AIRFLOW_CTX_DAG_RUN_ID='scheduled__2023-09-03T00:00:00+00:00'
[2023-09-18T13:52:31.958+0000] {subprocess.py:63} INFO - Tmp dir root location: /tmp
[2023-09-18T13:52:31.960+0000] {subprocess.py:75} INFO - Running command: ['/bin/bash', '-c', "sleep 2 && echo 'Task 2'"]
[2023-09-18T13:52:31.970+0000] {subprocess.py:86} INFO - Output:
[2023-09-18T13:52:33.975+0000] {subprocess.py:93} INFO - Task 2
[2023-09-18T13:52:33.976+0000] {subprocess.py:97} INFO - Command exited with return code 0
[2023-09-18T13:52:34.024+0000] {taskinstance.py:1398} INFO - Marking task as SUCCESS. dag_id=6.1-monitoring, task_id=task2, execution_date=20230903T000000, start_date=20230918T135231, end_date=20230918T135234
[2023-09-18T13:52:34.080+0000] {local_task_job_runner.py:228} INFO - Task exited with return code 0
[2023-09-18T13:52:34.217+0000] {taskinstance.py:2776} INFO - 0 downstream tasks scheduled from follow-on schedule check
[2023-09-18T13:54:47.216+0000] {taskinstance.py:1157} INFO - Dependencies all met for dep_context=non-requeueable deps ti=<TaskInstance: 6.1-monitoring.task2 scheduled__2023-09-03T00:00:00+00:00 [queued]>
[2023-09-18T13:54:47.331+0000] {taskinstance.py:1157} INFO - Dependencies all met for dep_context=requeueable deps ti=<TaskInstance: 6.1-monitoring.task2 scheduled__2023-09-03T00:00:00+00:00 [queued]>
[2023-09-18T13:54:47.333+0000] {taskinstance.py:1359} INFO - Starting attempt 1 of 1
[2023-09-18T13:54:47.405+0000] {taskinstance.py:1380} INFO - Executing <Task(BashOperator): task2> on 2023-09-03 00:00:00+00:00
[2023-09-18T13:54:47.422+0000] {standard_task_runner.py:57} INFO - Started process 5243 to run task
[2023-09-18T13:54:47.433+0000] {standard_task_runner.py:84} INFO - Running: ['***', 'tasks', 'run', '6.1-monitoring', 'task2', 'scheduled__2023-09-03T00:00:00+00:00', '--job-id', '441', '--raw', '--subdir', 'DAGS_FOLDER/6.1-monitoring.py', '--cfg-path', '/tmp/tmp5awsz8a4']
[2023-09-18T13:54:47.440+0000] {standard_task_runner.py:85} INFO - Job 441: Subtask task2
[2023-09-18T13:54:47.613+0000] {task_command.py:415} INFO - Running <TaskInstance: 6.1-monitoring.task2 scheduled__2023-09-03T00:00:00+00:00 [running]> on host e891a57bf0af
[2023-09-18T13:54:47.925+0000] {taskinstance.py:1660} INFO - Exporting env vars: AIRFLOW_CTX_DAG_OWNER='***' AIRFLOW_CTX_DAG_ID='6.1-monitoring' AIRFLOW_CTX_TASK_ID='task2' AIRFLOW_CTX_EXECUTION_DATE='2023-09-03T00:00:00+00:00' AIRFLOW_CTX_TRY_NUMBER='1' AIRFLOW_CTX_DAG_RUN_ID='scheduled__2023-09-03T00:00:00+00:00'
[2023-09-18T13:54:47.933+0000] {subprocess.py:63} INFO - Tmp dir root location: /tmp
[2023-09-18T13:54:47.935+0000] {subprocess.py:75} INFO - Running command: ['/bin/bash', '-c', "sleep 2 && echo 'Task 2'"]
[2023-09-18T13:54:47.981+0000] {subprocess.py:86} INFO - Output:
[2023-09-18T13:54:53.185+0000] {subprocess.py:93} INFO - Task 2
[2023-09-18T13:55:00.156+0000] {subprocess.py:97} INFO - Command exited with return code 0
[2023-09-18T13:55:11.433+0000] {job.py:219} ERROR - Job heartbeat got an exception
Traceback (most recent call last):
  File "/home/airflow/.local/lib/python3.8/site-packages/sqlalchemy/engine/base.py", line 3371, in _wrap_pool_connect
    return fn()
  File "/home/airflow/.local/lib/python3.8/site-packages/sqlalchemy/pool/base.py", line 327, in connect
    return _ConnectionFairy._checkout(self)
  File "/home/airflow/.local/lib/python3.8/site-packages/sqlalchemy/pool/base.py", line 894, in _checkout
    fairy = _ConnectionRecord.checkout(pool)
  File "/home/airflow/.local/lib/python3.8/site-packages/sqlalchemy/pool/base.py", line 493, in checkout
    rec = pool._do_get()
  File "/home/airflow/.local/lib/python3.8/site-packages/sqlalchemy/pool/impl.py", line 256, in _do_get
    return self._create_connection()
  File "/home/airflow/.local/lib/python3.8/site-packages/sqlalchemy/pool/base.py", line 273, in _create_connection
    return _ConnectionRecord(self)
  File "/home/airflow/.local/lib/python3.8/site-packages/sqlalchemy/pool/base.py", line 388, in __init__
    self.__connect()
  File "/home/airflow/.local/lib/python3.8/site-packages/sqlalchemy/pool/base.py", line 691, in __connect
    pool.logger.debug("Error on connect(): %s", e)
  File "/home/airflow/.local/lib/python3.8/site-packages/sqlalchemy/util/langhelpers.py", line 70, in __exit__
    compat.raise_(
  File "/home/airflow/.local/lib/python3.8/site-packages/sqlalchemy/util/compat.py", line 211, in raise_
    raise exception
  File "/home/airflow/.local/lib/python3.8/site-packages/sqlalchemy/pool/base.py", line 686, in __connect
    self.dbapi_connection = connection = pool._invoke_creator(self)
  File "/home/airflow/.local/lib/python3.8/site-packages/sqlalchemy/engine/create.py", line 574, in connect
    return dialect.connect(*cargs, **cparams)
  File "/home/airflow/.local/lib/python3.8/site-packages/sqlalchemy/engine/default.py", line 598, in connect
    return self.dbapi.connect(*cargs, **cparams)
  File "/home/airflow/.local/lib/python3.8/site-packages/psycopg2/__init__.py", line 122, in connect
    conn = _connect(dsn, connection_factory=connection_factory, **kwasync)
psycopg2.OperationalError: could not translate host name "postgres" to address: Temporary failure in name resolution


The above exception was the direct cause of the following exception:

Traceback (most recent call last):
  File "/home/airflow/.local/lib/python3.8/site-packages/airflow/jobs/job.py", line 215, in heartbeat
    heartbeat_callback(session)
  File "/home/airflow/.local/lib/python3.8/site-packages/airflow/utils/session.py", line 74, in wrapper
    return func(*args, **kwargs)
  File "/home/airflow/.local/lib/python3.8/site-packages/airflow/jobs/local_task_job_runner.py", line 246, in heartbeat_callback
    self.task_instance.refresh_from_db()
  File "/home/airflow/.local/lib/python3.8/site-packages/airflow/utils/session.py", line 77, in wrapper
    return func(*args, session=session, **kwargs)
  File "/home/airflow/.local/lib/python3.8/site-packages/airflow/models/taskinstance.py", line 864, in refresh_from_db
    ti = qry.one_or_none()
  File "/home/airflow/.local/lib/python3.8/site-packages/sqlalchemy/orm/query.py", line 2850, in one_or_none
    return self._iter().one_or_none()
  File "/home/airflow/.local/lib/python3.8/site-packages/sqlalchemy/orm/query.py", line 2916, in _iter
    result = self.session.execute(
  File "/home/airflow/.local/lib/python3.8/site-packages/sqlalchemy/orm/session.py", line 1716, in execute
    conn = self._connection_for_bind(bind)
  File "/home/airflow/.local/lib/python3.8/site-packages/sqlalchemy/orm/session.py", line 1555, in _connection_for_bind
    return self._transaction._connection_for_bind(
  File "/home/airflow/.local/lib/python3.8/site-packages/sqlalchemy/orm/session.py", line 750, in _connection_for_bind
    conn = bind.connect()
  File "/home/airflow/.local/lib/python3.8/site-packages/sqlalchemy/future/engine.py", line 406, in connect
    return super(Engine, self).connect()
  File "/home/airflow/.local/lib/python3.8/site-packages/sqlalchemy/engine/base.py", line 3325, in connect
    return self._connection_cls(self, close_with_result=close_with_result)
  File "/home/airflow/.local/lib/python3.8/site-packages/sqlalchemy/engine/base.py", line 96, in __init__
    else engine.raw_connection()
  File "/home/airflow/.local/lib/python3.8/site-packages/sqlalchemy/engine/base.py", line 3404, in raw_connection
    return self._wrap_pool_connect(self.pool.connect, _connection)
  File "/home/airflow/.local/lib/python3.8/site-packages/sqlalchemy/engine/base.py", line 3374, in _wrap_pool_connect
    Connection._handle_dbapi_exception_noconnection(
  File "/home/airflow/.local/lib/python3.8/site-packages/sqlalchemy/engine/base.py", line 2208, in _handle_dbapi_exception_noconnection
    util.raise_(
  File "/home/airflow/.local/lib/python3.8/site-packages/sqlalchemy/util/compat.py", line 211, in raise_
    raise exception
  File "/home/airflow/.local/lib/python3.8/site-packages/sqlalchemy/engine/base.py", line 3371, in _wrap_pool_connect
    return fn()
  File "/home/airflow/.local/lib/python3.8/site-packages/sqlalchemy/pool/base.py", line 327, in connect
    return _ConnectionFairy._checkout(self)
  File "/home/airflow/.local/lib/python3.8/site-packages/sqlalchemy/pool/base.py", line 894, in _checkout
    fairy = _ConnectionRecord.checkout(pool)
  File "/home/airflow/.local/lib/python3.8/site-packages/sqlalchemy/pool/base.py", line 493, in checkout
    rec = pool._do_get()
  File "/home/airflow/.local/lib/python3.8/site-packages/sqlalchemy/pool/impl.py", line 256, in _do_get
    return self._create_connection()
  File "/home/airflow/.local/lib/python3.8/site-packages/sqlalchemy/pool/base.py", line 273, in _create_connection
    return _ConnectionRecord(self)
  File "/home/airflow/.local/lib/python3.8/site-packages/sqlalchemy/pool/base.py", line 388, in __init__
    self.__connect()
  File "/home/airflow/.local/lib/python3.8/site-packages/sqlalchemy/pool/base.py", line 691, in __connect
    pool.logger.debug("Error on connect(): %s", e)
  File "/home/airflow/.local/lib/python3.8/site-packages/sqlalchemy/util/langhelpers.py", line 70, in __exit__
    compat.raise_(
  File "/home/airflow/.local/lib/python3.8/site-packages/sqlalchemy/util/compat.py", line 211, in raise_
    raise exception
  File "/home/airflow/.local/lib/python3.8/site-packages/sqlalchemy/pool/base.py", line 686, in __connect
    self.dbapi_connection = connection = pool._invoke_creator(self)
  File "/home/airflow/.local/lib/python3.8/site-packages/sqlalchemy/engine/create.py", line 574, in connect
    return dialect.connect(*cargs, **cparams)
  File "/home/airflow/.local/lib/python3.8/site-packages/sqlalchemy/engine/default.py", line 598, in connect
    return self.dbapi.connect(*cargs, **cparams)
  File "/home/airflow/.local/lib/python3.8/site-packages/psycopg2/__init__.py", line 122, in connect
    conn = _connect(dsn, connection_factory=connection_factory, **kwasync)
sqlalchemy.exc.OperationalError: (psycopg2.OperationalError) could not translate host name "postgres" to address: Temporary failure in name resolution

(Background on this error at: https://sqlalche.me/e/14/e3q8)
[2023-09-18T13:55:12.370+0000] {taskinstance.py:1398} INFO - Marking task as SUCCESS. dag_id=6.1-monitoring, task_id=task2, execution_date=20230903T000000, start_date=20230918T135447, end_date=20230918T135512
[2023-09-18T13:55:12.481+0000] {local_task_job_runner.py:228} INFO - Task exited with return code 0
[2023-09-18T13:55:12.997+0000] {taskinstance.py:2776} INFO - 1 downstream tasks scheduled from follow-on schedule check
