[2023-09-18T13:45:48.694+0000] {taskinstance.py:1157} INFO - Dependencies all met for dep_context=non-requeueable deps ti=<TaskInstance: 6.1-monitoring.task2 scheduled__2023-08-08T00:00:00+00:00 [queued]>
[2023-09-18T13:45:48.715+0000] {taskinstance.py:1157} INFO - Dependencies all met for dep_context=requeueable deps ti=<TaskInstance: 6.1-monitoring.task2 scheduled__2023-08-08T00:00:00+00:00 [queued]>
[2023-09-18T13:45:48.716+0000] {taskinstance.py:1359} INFO - Starting attempt 1 of 1
[2023-09-18T13:45:48.760+0000] {taskinstance.py:1380} INFO - Executing <Task(BashOperator): task2> on 2023-08-08 00:00:00+00:00
[2023-09-18T13:45:48.770+0000] {standard_task_runner.py:57} INFO - Started process 4283 to run task
[2023-09-18T13:45:48.777+0000] {standard_task_runner.py:84} INFO - Running: ['***', 'tasks', 'run', '6.1-monitoring', 'task2', 'scheduled__2023-08-08T00:00:00+00:00', '--job-id', '209', '--raw', '--subdir', 'DAGS_FOLDER/6.1-monitoring.py', '--cfg-path', '/tmp/tmp8f6p0tqa']
[2023-09-18T13:45:48.779+0000] {standard_task_runner.py:85} INFO - Job 209: Subtask task2
[2023-09-18T13:45:48.891+0000] {task_command.py:415} INFO - Running <TaskInstance: 6.1-monitoring.task2 scheduled__2023-08-08T00:00:00+00:00 [running]> on host e891a57bf0af
[2023-09-18T13:45:49.052+0000] {taskinstance.py:1660} INFO - Exporting env vars: AIRFLOW_CTX_DAG_OWNER='***' AIRFLOW_CTX_DAG_ID='6.1-monitoring' AIRFLOW_CTX_TASK_ID='task2' AIRFLOW_CTX_EXECUTION_DATE='2023-08-08T00:00:00+00:00' AIRFLOW_CTX_TRY_NUMBER='1' AIRFLOW_CTX_DAG_RUN_ID='scheduled__2023-08-08T00:00:00+00:00'
[2023-09-18T13:45:49.057+0000] {subprocess.py:63} INFO - Tmp dir root location: /tmp
[2023-09-18T13:45:49.060+0000] {subprocess.py:75} INFO - Running command: ['/bin/bash', '-c', "sleep 2 && echo 'Task 2"]
[2023-09-18T13:45:49.081+0000] {subprocess.py:86} INFO - Output:
[2023-09-18T13:45:49.083+0000] {subprocess.py:93} INFO - /bin/bash: -c: line 1: unexpected EOF while looking for matching `''
[2023-09-18T13:45:49.084+0000] {subprocess.py:93} INFO - /bin/bash: -c: line 2: syntax error: unexpected end of file
[2023-09-18T13:45:49.085+0000] {subprocess.py:97} INFO - Command exited with return code 2
[2023-09-18T13:45:49.114+0000] {taskinstance.py:1935} ERROR - Task failed with exception
Traceback (most recent call last):
  File "/home/airflow/.local/lib/python3.8/site-packages/airflow/operators/bash.py", line 210, in execute
    raise AirflowException(
airflow.exceptions.AirflowException: Bash command failed. The command returned a non-zero exit code 2.
[2023-09-18T13:45:49.120+0000] {taskinstance.py:1398} INFO - Marking task as FAILED. dag_id=6.1-monitoring, task_id=task2, execution_date=20230808T000000, start_date=20230918T134548, end_date=20230918T134549
[2023-09-18T13:45:49.145+0000] {standard_task_runner.py:104} ERROR - Failed to execute job 209 for task task2 (Bash command failed. The command returned a non-zero exit code 2.; 4283)
[2023-09-18T13:45:49.193+0000] {local_task_job_runner.py:228} INFO - Task exited with return code 1
[2023-09-18T13:45:49.241+0000] {taskinstance.py:2776} INFO - 0 downstream tasks scheduled from follow-on schedule check
