[2023-09-18T13:45:58.711+0000] {taskinstance.py:1157} INFO - Dependencies all met for dep_context=non-requeueable deps ti=<TaskInstance: 6.1-monitoring.task1 scheduled__2023-08-26T00:00:00+00:00 [queued]>
[2023-09-18T13:45:58.761+0000] {taskinstance.py:1157} INFO - Dependencies all met for dep_context=requeueable deps ti=<TaskInstance: 6.1-monitoring.task1 scheduled__2023-08-26T00:00:00+00:00 [queued]>
[2023-09-18T13:45:58.763+0000] {taskinstance.py:1359} INFO - Starting attempt 1 of 1
[2023-09-18T13:45:58.829+0000] {taskinstance.py:1380} INFO - Executing <Task(BashOperator): task1> on 2023-08-26 00:00:00+00:00
[2023-09-18T13:45:58.844+0000] {standard_task_runner.py:57} INFO - Started process 4337 to run task
[2023-09-18T13:45:59.584+0000] {standard_task_runner.py:84} INFO - Running: ['***', 'tasks', 'run', '6.1-monitoring', 'task1', 'scheduled__2023-08-26T00:00:00+00:00', '--job-id', '223', '--raw', '--subdir', 'DAGS_FOLDER/6.1-monitoring.py', '--cfg-path', '/tmp/tmpnufbjrtd']
[2023-09-18T13:45:59.645+0000] {standard_task_runner.py:85} INFO - Job 223: Subtask task1
[2023-09-18T13:46:14.300+0000] {job.py:219} ERROR - Job heartbeat got an exception
Traceback (most recent call last):
  File "/home/airflow/.local/lib/python3.8/site-packages/sqlalchemy/engine/base.py", line 3371, in _wrap_pool_connect
    return fn()
  File "/home/airflow/.local/lib/python3.8/site-packages/sqlalchemy/pool/base.py", line 327, in connect
    return _ConnectionFairy._checkout(self)
  File "/home/airflow/.local/lib/python3.8/site-packages/sqlalchemy/pool/base.py", line 894, in _checkout
    fairy = _ConnectionRecord.checkout(pool)
  File "/home/airflow/.local/lib/python3.8/site-packages/sqlalchemy/pool/base.py", line 493, in checkout
    rec = pool._do_get()
  File "/home/airflow/.local/lib/python3.8/site-packages/sqlalchemy/pool/impl.py", line 256, in _do_get
    return self._create_connection()
  File "/home/airflow/.local/lib/python3.8/site-packages/sqlalchemy/pool/base.py", line 273, in _create_connection
    return _ConnectionRecord(self)
  File "/home/airflow/.local/lib/python3.8/site-packages/sqlalchemy/pool/base.py", line 388, in __init__
    self.__connect()
  File "/home/airflow/.local/lib/python3.8/site-packages/sqlalchemy/pool/base.py", line 691, in __connect
    pool.logger.debug("Error on connect(): %s", e)
  File "/home/airflow/.local/lib/python3.8/site-packages/sqlalchemy/util/langhelpers.py", line 70, in __exit__
    compat.raise_(
  File "/home/airflow/.local/lib/python3.8/site-packages/sqlalchemy/util/compat.py", line 211, in raise_
    raise exception
  File "/home/airflow/.local/lib/python3.8/site-packages/sqlalchemy/pool/base.py", line 686, in __connect
    self.dbapi_connection = connection = pool._invoke_creator(self)
  File "/home/airflow/.local/lib/python3.8/site-packages/sqlalchemy/engine/create.py", line 574, in connect
    return dialect.connect(*cargs, **cparams)
  File "/home/airflow/.local/lib/python3.8/site-packages/sqlalchemy/engine/default.py", line 598, in connect
    return self.dbapi.connect(*cargs, **cparams)
  File "/home/airflow/.local/lib/python3.8/site-packages/psycopg2/__init__.py", line 122, in connect
    conn = _connect(dsn, connection_factory=connection_factory, **kwasync)
psycopg2.OperationalError: could not translate host name "postgres" to address: Temporary failure in name resolution


The above exception was the direct cause of the following exception:

Traceback (most recent call last):
  File "/home/airflow/.local/lib/python3.8/site-packages/airflow/jobs/job.py", line 190, in heartbeat
    session.merge(self)
  File "/home/airflow/.local/lib/python3.8/site-packages/sqlalchemy/orm/session.py", line 3056, in merge
    return self._merge(
  File "/home/airflow/.local/lib/python3.8/site-packages/sqlalchemy/orm/session.py", line 3136, in _merge
    merged = self.get(
  File "/home/airflow/.local/lib/python3.8/site-packages/sqlalchemy/orm/session.py", line 2853, in get
    return self._get_impl(
  File "/home/airflow/.local/lib/python3.8/site-packages/sqlalchemy/orm/session.py", line 2975, in _get_impl
    return db_load_fn(
  File "/home/airflow/.local/lib/python3.8/site-packages/sqlalchemy/orm/loading.py", line 530, in load_on_pk_identity
    session.execute(
  File "/home/airflow/.local/lib/python3.8/site-packages/sqlalchemy/orm/session.py", line 1716, in execute
    conn = self._connection_for_bind(bind)
  File "/home/airflow/.local/lib/python3.8/site-packages/sqlalchemy/orm/session.py", line 1555, in _connection_for_bind
    return self._transaction._connection_for_bind(
  File "/home/airflow/.local/lib/python3.8/site-packages/sqlalchemy/orm/session.py", line 750, in _connection_for_bind
    conn = bind.connect()
  File "/home/airflow/.local/lib/python3.8/site-packages/sqlalchemy/future/engine.py", line 406, in connect
    return super(Engine, self).connect()
  File "/home/airflow/.local/lib/python3.8/site-packages/sqlalchemy/engine/base.py", line 3325, in connect
    return self._connection_cls(self, close_with_result=close_with_result)
  File "/home/airflow/.local/lib/python3.8/site-packages/sqlalchemy/engine/base.py", line 96, in __init__
    else engine.raw_connection()
  File "/home/airflow/.local/lib/python3.8/site-packages/sqlalchemy/engine/base.py", line 3404, in raw_connection
    return self._wrap_pool_connect(self.pool.connect, _connection)
  File "/home/airflow/.local/lib/python3.8/site-packages/sqlalchemy/engine/base.py", line 3374, in _wrap_pool_connect
    Connection._handle_dbapi_exception_noconnection(
  File "/home/airflow/.local/lib/python3.8/site-packages/sqlalchemy/engine/base.py", line 2208, in _handle_dbapi_exception_noconnection
    util.raise_(
  File "/home/airflow/.local/lib/python3.8/site-packages/sqlalchemy/util/compat.py", line 211, in raise_
    raise exception
  File "/home/airflow/.local/lib/python3.8/site-packages/sqlalchemy/engine/base.py", line 3371, in _wrap_pool_connect
    return fn()
  File "/home/airflow/.local/lib/python3.8/site-packages/sqlalchemy/pool/base.py", line 327, in connect
    return _ConnectionFairy._checkout(self)
  File "/home/airflow/.local/lib/python3.8/site-packages/sqlalchemy/pool/base.py", line 894, in _checkout
    fairy = _ConnectionRecord.checkout(pool)
  File "/home/airflow/.local/lib/python3.8/site-packages/sqlalchemy/pool/base.py", line 493, in checkout
    rec = pool._do_get()
  File "/home/airflow/.local/lib/python3.8/site-packages/sqlalchemy/pool/impl.py", line 256, in _do_get
    return self._create_connection()
  File "/home/airflow/.local/lib/python3.8/site-packages/sqlalchemy/pool/base.py", line 273, in _create_connection
    return _ConnectionRecord(self)
  File "/home/airflow/.local/lib/python3.8/site-packages/sqlalchemy/pool/base.py", line 388, in __init__
    self.__connect()
  File "/home/airflow/.local/lib/python3.8/site-packages/sqlalchemy/pool/base.py", line 691, in __connect
    pool.logger.debug("Error on connect(): %s", e)
  File "/home/airflow/.local/lib/python3.8/site-packages/sqlalchemy/util/langhelpers.py", line 70, in __exit__
    compat.raise_(
  File "/home/airflow/.local/lib/python3.8/site-packages/sqlalchemy/util/compat.py", line 211, in raise_
    raise exception
  File "/home/airflow/.local/lib/python3.8/site-packages/sqlalchemy/pool/base.py", line 686, in __connect
    self.dbapi_connection = connection = pool._invoke_creator(self)
  File "/home/airflow/.local/lib/python3.8/site-packages/sqlalchemy/engine/create.py", line 574, in connect
    return dialect.connect(*cargs, **cparams)
  File "/home/airflow/.local/lib/python3.8/site-packages/sqlalchemy/engine/default.py", line 598, in connect
    return self.dbapi.connect(*cargs, **cparams)
  File "/home/airflow/.local/lib/python3.8/site-packages/psycopg2/__init__.py", line 122, in connect
    conn = _connect(dsn, connection_factory=connection_factory, **kwasync)
sqlalchemy.exc.OperationalError: (psycopg2.OperationalError) could not translate host name "postgres" to address: Temporary failure in name resolution

(Background on this error at: https://sqlalche.me/e/14/e3q8)
[2023-09-18T13:46:22.444+0000] {task_command.py:415} INFO - Running <TaskInstance: 6.1-monitoring.task1 scheduled__2023-08-26T00:00:00+00:00 [running]> on host e891a57bf0af
[2023-09-18T13:46:22.724+0000] {taskinstance.py:1660} INFO - Exporting env vars: AIRFLOW_CTX_DAG_OWNER='***' AIRFLOW_CTX_DAG_ID='6.1-monitoring' AIRFLOW_CTX_TASK_ID='task1' AIRFLOW_CTX_EXECUTION_DATE='2023-08-26T00:00:00+00:00' AIRFLOW_CTX_TRY_NUMBER='1' AIRFLOW_CTX_DAG_RUN_ID='scheduled__2023-08-26T00:00:00+00:00'
[2023-09-18T13:46:22.731+0000] {subprocess.py:63} INFO - Tmp dir root location: /tmp
[2023-09-18T13:46:22.740+0000] {subprocess.py:75} INFO - Running command: ['/bin/bash', '-c', "sleep 2 && echo 'Task 1'"]
[2023-09-18T13:46:22.770+0000] {subprocess.py:86} INFO - Output:
[2023-09-18T13:46:24.892+0000] {subprocess.py:93} INFO - Task 1
[2023-09-18T13:46:24.893+0000] {subprocess.py:97} INFO - Command exited with return code 0
[2023-09-18T13:46:24.986+0000] {taskinstance.py:1398} INFO - Marking task as SUCCESS. dag_id=6.1-monitoring, task_id=task1, execution_date=20230826T000000, start_date=20230918T134558, end_date=20230918T134624
[2023-09-18T13:46:25.047+0000] {local_task_job_runner.py:228} INFO - Task exited with return code 0
[2023-09-18T13:46:25.144+0000] {taskinstance.py:2776} INFO - 1 downstream tasks scheduled from follow-on schedule check
[2023-09-18T13:52:00.652+0000] {taskinstance.py:1157} INFO - Dependencies all met for dep_context=non-requeueable deps ti=<TaskInstance: 6.1-monitoring.task1 scheduled__2023-08-26T00:00:00+00:00 [queued]>
[2023-09-18T13:52:00.692+0000] {taskinstance.py:1157} INFO - Dependencies all met for dep_context=requeueable deps ti=<TaskInstance: 6.1-monitoring.task1 scheduled__2023-08-26T00:00:00+00:00 [queued]>
[2023-09-18T13:52:00.694+0000] {taskinstance.py:1359} INFO - Starting attempt 1 of 1
[2023-09-18T13:52:00.727+0000] {taskinstance.py:1380} INFO - Executing <Task(BashOperator): task1> on 2023-08-26 00:00:00+00:00
[2023-09-18T13:52:00.736+0000] {standard_task_runner.py:57} INFO - Started process 4737 to run task
[2023-09-18T13:52:00.743+0000] {standard_task_runner.py:84} INFO - Running: ['***', 'tasks', 'run', '6.1-monitoring', 'task1', 'scheduled__2023-08-26T00:00:00+00:00', '--job-id', '312', '--raw', '--subdir', 'DAGS_FOLDER/6.1-monitoring.py', '--cfg-path', '/tmp/tmprrzby2gc']
[2023-09-18T13:52:00.746+0000] {standard_task_runner.py:85} INFO - Job 312: Subtask task1
[2023-09-18T13:52:00.885+0000] {task_command.py:415} INFO - Running <TaskInstance: 6.1-monitoring.task1 scheduled__2023-08-26T00:00:00+00:00 [running]> on host e891a57bf0af
[2023-09-18T13:52:01.145+0000] {taskinstance.py:1660} INFO - Exporting env vars: AIRFLOW_CTX_DAG_OWNER='***' AIRFLOW_CTX_DAG_ID='6.1-monitoring' AIRFLOW_CTX_TASK_ID='task1' AIRFLOW_CTX_EXECUTION_DATE='2023-08-26T00:00:00+00:00' AIRFLOW_CTX_TRY_NUMBER='1' AIRFLOW_CTX_DAG_RUN_ID='scheduled__2023-08-26T00:00:00+00:00'
[2023-09-18T13:52:01.148+0000] {subprocess.py:63} INFO - Tmp dir root location: /tmp
[2023-09-18T13:52:01.149+0000] {subprocess.py:75} INFO - Running command: ['/bin/bash', '-c', "sleep 2 && echo 'Task 1'"]
[2023-09-18T13:52:01.172+0000] {subprocess.py:86} INFO - Output:
[2023-09-18T13:52:03.211+0000] {subprocess.py:93} INFO - Task 1
[2023-09-18T13:52:03.214+0000] {subprocess.py:97} INFO - Command exited with return code 0
[2023-09-18T13:52:04.166+0000] {taskinstance.py:1398} INFO - Marking task as SUCCESS. dag_id=6.1-monitoring, task_id=task1, execution_date=20230826T000000, start_date=20230918T135200, end_date=20230918T135204
[2023-09-18T13:52:04.274+0000] {local_task_job_runner.py:228} INFO - Task exited with return code 0
[2023-09-18T13:52:04.426+0000] {taskinstance.py:2776} INFO - 1 downstream tasks scheduled from follow-on schedule check
