[2023-09-18T13:45:25.942+0000] {taskinstance.py:1157} INFO - Dependencies all met for dep_context=non-requeueable deps ti=<TaskInstance: 6.1-monitoring.task2 scheduled__2023-08-01T00:00:00+00:00 [queued]>
[2023-09-18T13:45:25.970+0000] {taskinstance.py:1157} INFO - Dependencies all met for dep_context=requeueable deps ti=<TaskInstance: 6.1-monitoring.task2 scheduled__2023-08-01T00:00:00+00:00 [queued]>
[2023-09-18T13:45:25.972+0000] {taskinstance.py:1359} INFO - Starting attempt 1 of 1
[2023-09-18T13:45:26.333+0000] {taskinstance.py:1380} INFO - Executing <Task(BashOperator): task2> on 2023-08-01 00:00:00+00:00
[2023-09-18T13:45:26.347+0000] {standard_task_runner.py:57} INFO - Started process 4220 to run task
[2023-09-18T13:45:26.360+0000] {standard_task_runner.py:84} INFO - Running: ['***', 'tasks', 'run', '6.1-monitoring', 'task2', 'scheduled__2023-08-01T00:00:00+00:00', '--job-id', '195', '--raw', '--subdir', 'DAGS_FOLDER/6.1-monitoring.py', '--cfg-path', '/tmp/tmp2_xj508b']
[2023-09-18T13:45:26.368+0000] {standard_task_runner.py:85} INFO - Job 195: Subtask task2
[2023-09-18T13:45:26.642+0000] {task_command.py:415} INFO - Running <TaskInstance: 6.1-monitoring.task2 scheduled__2023-08-01T00:00:00+00:00 [running]> on host e891a57bf0af
[2023-09-18T13:45:26.874+0000] {taskinstance.py:1660} INFO - Exporting env vars: AIRFLOW_CTX_DAG_OWNER='***' AIRFLOW_CTX_DAG_ID='6.1-monitoring' AIRFLOW_CTX_TASK_ID='task2' AIRFLOW_CTX_EXECUTION_DATE='2023-08-01T00:00:00+00:00' AIRFLOW_CTX_TRY_NUMBER='1' AIRFLOW_CTX_DAG_RUN_ID='scheduled__2023-08-01T00:00:00+00:00'
[2023-09-18T13:45:26.877+0000] {subprocess.py:63} INFO - Tmp dir root location: /tmp
[2023-09-18T13:45:26.886+0000] {subprocess.py:75} INFO - Running command: ['/bin/bash', '-c', "sleep 2 && echo 'Task 2"]
[2023-09-18T13:45:26.903+0000] {subprocess.py:86} INFO - Output:
[2023-09-18T13:45:26.905+0000] {subprocess.py:93} INFO - /bin/bash: -c: line 1: unexpected EOF while looking for matching `''
[2023-09-18T13:45:26.906+0000] {subprocess.py:93} INFO - /bin/bash: -c: line 2: syntax error: unexpected end of file
[2023-09-18T13:45:26.907+0000] {subprocess.py:97} INFO - Command exited with return code 2
[2023-09-18T13:45:26.937+0000] {taskinstance.py:1935} ERROR - Task failed with exception
Traceback (most recent call last):
  File "/home/airflow/.local/lib/python3.8/site-packages/airflow/operators/bash.py", line 210, in execute
    raise AirflowException(
airflow.exceptions.AirflowException: Bash command failed. The command returned a non-zero exit code 2.
[2023-09-18T13:45:26.959+0000] {taskinstance.py:1398} INFO - Marking task as FAILED. dag_id=6.1-monitoring, task_id=task2, execution_date=20230801T000000, start_date=20230918T134525, end_date=20230918T134526
[2023-09-18T13:45:27.013+0000] {standard_task_runner.py:104} ERROR - Failed to execute job 195 for task task2 (Bash command failed. The command returned a non-zero exit code 2.; 4220)
[2023-09-18T13:45:27.063+0000] {local_task_job_runner.py:228} INFO - Task exited with return code 1
[2023-09-18T13:45:27.125+0000] {taskinstance.py:2776} INFO - 0 downstream tasks scheduled from follow-on schedule check
