[2023-09-19T12:19:35.900+0000] {taskinstance.py:1157} INFO - Dependencies all met for dep_context=non-requeueable deps ti=<TaskInstance: 6.2-monitoring.task4 scheduled__2023-09-02T00:00:00+00:00 [queued]>
[2023-09-19T12:19:35.914+0000] {taskinstance.py:1157} INFO - Dependencies all met for dep_context=requeueable deps ti=<TaskInstance: 6.2-monitoring.task4 scheduled__2023-09-02T00:00:00+00:00 [queued]>
[2023-09-19T12:19:35.915+0000] {taskinstance.py:1359} INFO - Starting attempt 3 of 3
[2023-09-19T12:19:35.936+0000] {taskinstance.py:1380} INFO - Executing <Task(PythonOperator): task4> on 2023-09-02 00:00:00+00:00
[2023-09-19T12:19:35.943+0000] {standard_task_runner.py:57} INFO - Started process 199 to run task
[2023-09-19T12:19:35.946+0000] {standard_task_runner.py:84} INFO - Running: ['***', 'tasks', 'run', '6.2-monitoring', 'task4', 'scheduled__2023-09-02T00:00:00+00:00', '--job-id', '537', '--raw', '--subdir', 'DAGS_FOLDER/6.2-monitoring.py', '--cfg-path', '/tmp/tmp0smcmzy8']
[2023-09-19T12:19:35.948+0000] {standard_task_runner.py:85} INFO - Job 537: Subtask task4
[2023-09-19T12:19:36.000+0000] {task_command.py:415} INFO - Running <TaskInstance: 6.2-monitoring.task4 scheduled__2023-09-02T00:00:00+00:00 [running]> on host e891a57bf0af
[2023-09-19T12:19:36.079+0000] {taskinstance.py:1660} INFO - Exporting env vars: AIRFLOW_CTX_DAG_OWNER='***' AIRFLOW_CTX_DAG_ID='6.2-monitoring' AIRFLOW_CTX_TASK_ID='task4' AIRFLOW_CTX_EXECUTION_DATE='2023-09-02T00:00:00+00:00' AIRFLOW_CTX_TRY_NUMBER='3' AIRFLOW_CTX_DAG_RUN_ID='scheduled__2023-09-02T00:00:00+00:00'
[2023-09-19T12:19:36.081+0000] {taskinstance.py:1935} ERROR - Task failed with exception
Traceback (most recent call last):
  File "/home/airflow/.local/lib/python3.8/site-packages/airflow/operators/python.py", line 192, in execute
    return_value = self.execute_callable()
  File "/home/airflow/.local/lib/python3.8/site-packages/airflow/operators/python.py", line 209, in execute_callable
    return self.python_callable(*self.op_args, **self.op_kwargs)
  File "/opt/airflow/dags/6.2-monitoring.py", line 9, in myfunction
    raise Exception
Exception
[2023-09-19T12:19:36.093+0000] {taskinstance.py:1398} INFO - Marking task as FAILED. dag_id=6.2-monitoring, task_id=task4, execution_date=20230902T000000, start_date=20230919T121935, end_date=20230919T121936
[2023-09-19T12:19:36.105+0000] {standard_task_runner.py:104} ERROR - Failed to execute job 537 for task task4 (; 199)
[2023-09-19T12:19:36.119+0000] {local_task_job_runner.py:228} INFO - Task exited with return code 1
[2023-09-19T12:19:36.148+0000] {taskinstance.py:2776} INFO - 0 downstream tasks scheduled from follow-on schedule check
